#VRML_SIM R2025a utf8

EXTERNPROTO "https://raw.githubusercontent.com/cyberbotics/webots/R2025a/projects/objects/backgrounds/protos/TexturedBackground.proto"
EXTERNPROTO "https://raw.githubusercontent.com/cyberbotics/webots/R2025a/projects/objects/backgrounds/protos/TexturedBackgroundLight.proto"
EXTERNPROTO "https://raw.githubusercontent.com/cyberbotics/webots/R2025a/projects/objects/floors/protos/RectangleArena.proto"

WorldInfo {
  info [
    "Thanks to Mehdi Ghanavati, Shahid Chamran University"
  ]
  title "Omni-wheels"
  basicTimeStep 8
}
Viewpoint {
  orientation -0.017922603290154566 0.9998385417247575 -0.00129258385187661 0.6740839404379427
  position -6.694205640079527 0.13282631209199314 4.982480021548608
}
TexturedBackground {
}
TexturedBackgroundLight {
}
RectangleArena {
  floorSize 5 5
}
DEF OMNI_WHEELS Robot {
  translation -5.56401148786735e-07 1.4387413302653893e-06 0.05948726595448299
  rotation -0.931547160057962 -0.3636205162974813 9.335683563815734e-05 2.5718600909653586e-05
  children [
    DEF SOLID1 Solid {
      children [
        DEF WHEEL1 HingeJoint {
          jointParameters HingeJointParameters {
            position -1.243195715261436e-07
            axis -1 0 0
            anchor -0.1 0 0
          }
          device [
            RotationalMotor {
              name "wheel1"
            }
          ]
          endPoint Solid {
            translation -0.1 0 0
            rotation 1 0 0 1.2287812309317772e-07
            children [
              DEF sr1 HingeJoint {
                jointParameters HingeJointParameters {
                  position 9.22769558226969e-06
                  axis 0 1 0
                  anchor -0.02 0 0.05
                }
                endPoint Solid {
                  translation -0.02 0 0.05
                  rotation 0 1 0 9.227705742773864e-06
                  children [
                    DEF r1 Pose {
                      rotation -1 0 0 1.5708
                      children [
                        DEF SMALL_WHEEL_SHAPE Shape {
                          appearance PBRAppearance {
                            baseColor 1 0.752941 0.796078
                            roughness 1
                            metalness 0
                          }
                          geometry Cylinder {
                            height 0.02
                            radius 0.01
                          }
                        }
                      ]
                    }
                  ]
                  name "sr1"
                  boundingObject USE r1
                  physics Physics {
                    density -1
                    mass 0.1
                  }
                  linearVelocity -6.008911186659163e-08 -1.2056475171257752e-07 2.7040190290340412e-08
                  angularVelocity 1.1105959579134895e-06 5.492573340519315e-12 2.385213097629014e-07
                }
              }
              DEF sr2 HingeJoint {
                jointParameters HingeJointParameters {
                  position -6.433742754552441e-06
                  axis 0 -0.707107 0.707107
                  anchor -0.02 0.03535 0.03535
                }
                endPoint Solid {
                  translation -0.02 0.03535 0.03535
                  rotation 0 0.7071067811865476 -0.7071067811865476 6.433713319051474e-06
                  children [
                    DEF r2 Pose {
                      rotation -1 0 0 2.27
                      children [
                        USE SMALL_WHEEL_SHAPE
                      ]
                    }
                  ]
                  name "sr2"
                  boundingObject USE r2
                  physics Physics {
                    density -1
                    mass 0.1
                  }
                  linearVelocity -7.188758726979746e-08 -1.0429807405289628e-07 6.628841651867192e-08
                  angularVelocity 1.1105960308202805e-06 2.3762592212017695e-07 2.3090497185811316e-07
                }
              }
              DEF sr3 HingeJoint {
                jointParameters HingeJointParameters {
                  position -2.8108650873548413e-07
                  axis 0 1 0
                  anchor -0.02 0 -0.05
                }
                endPoint Solid {
                  translation -0.02 0 -0.05
                  rotation 0 -1 0 2.8115454709698594e-07
                  children [
                    DEF r3 Pose {
                      rotation -1 0 0 1.5708
                      children [
                        USE SMALL_WHEEL_SHAPE
                      ]
                    }
                  ]
                  name "sr3"
                  boundingObject USE r3
                  physics Physics {
                    density -1
                    mass 0.1
                  }
                  linearVelocity -8.30724348556135e-08 -1.061431787947141e-08 2.6507325009566626e-08
                  angularVelocity 1.1105829033056742e-06 -8.306729678087124e-06 2.3866947586389246e-07
                }
              }
              DEF sr4 HingeJoint {
                jointParameters HingeJointParameters {
                  position -6.433742754552441e-06
                  axis 0 -0.707107 0.707107
                  anchor -0.02 -0.03535 -0.03535
                }
                endPoint Solid {
                  translation -0.02 -0.03535 -0.03535
                  rotation 0 0.7071067811865476 -0.7071067811865476 6.433713319051474e-06
                  children [
                    DEF r4 Pose {
                      rotation -1 0 0 2.27
                      children [
                        USE SMALL_WHEEL_SHAPE
                      ]
                    }
                  ]
                  name "sr4"
                  boundingObject USE r4
                  physics Physics {
                    density -1
                    mass 0.1
                  }
                  linearVelocity -7.128521264953257e-08 -2.5802505082625504e-08 -1.2210908142646836e-08
                  angularVelocity 1.1105960291082685e-06 2.3762592368506106e-07 2.3090497337881947e-07
                }
              }
              DEF sr5 HingeJoint {
                jointParameters HingeJointParameters {
                  position -2.671693088984739e-09
                  axis 0 0 1
                  anchor -0.02 0.05 0
                }
                endPoint Solid {
                  translation -0.02 0.05 0
                  children [
                    DEF r5 Pose {
                      children [
                        USE SMALL_WHEEL_SHAPE
                      ]
                    }
                  ]
                  name "sr5"
                  boundingObject USE r5
                  physics Physics {
                    density -1
                    mass 0.1
                  }
                  linearVelocity -8.35096948636734e-08 -6.504895954799197e-08 8.255310638762075e-08
                  angularVelocity 1.1105981613676898e-06 2.3000974571156682e-07 4.7396811874923584e-12
                }
              }
              DEF sr6 HingeJoint {
                jointParameters HingeJointParameters {
                  position -2.671693088984739e-09
                  axis 0 0 1
                  anchor -0.02 -0.05 0
                }
                endPoint Solid {
                  translation -0.02 -0.05 0
                  children [
                    DEF r6 Pose {
                      children [
                        USE SMALL_WHEEL_SHAPE
                      ]
                    }
                  ]
                  name "sr6"
                  boundingObject USE r6
                  physics Physics {
                    density -1
                    mass 0.1
                  }
                  linearVelocity -5.966310474437208e-08 -6.50516193146559e-08 -2.8475598101453782e-08
                  angularVelocity 1.1105981614122958e-06 2.3000974587423494e-07 4.739681129092433e-12
                }
              }
              DEF sr7 HingeJoint {
                jointParameters HingeJointParameters {
                  position 6.550687030701894e-06
                  axis 0 0.707107 0.707107
                  anchor -0.02 0.03535 -0.03535
                }
                endPoint Solid {
                  translation -0.02 0.03535 -0.03535
                  rotation 0 0.7071067811865476 0.7071067811865476 6.550683336067331e-06
                  children [
                    DEF r7 Pose {
                      rotation -1 0 0 0.76
                      children [
                        USE SMALL_WHEEL_SHAPE
                      ]
                    }
                  ]
                  name "sr7"
                  boundingObject USE r7
                  physics Physics {
                    density -1
                    mass 0.1
                  }
                  linearVelocity -8.814475210019247e-08 -2.5800624538995354e-08 6.628638579614205e-08
                  angularVelocity 1.1105981280099653e-06 -4.234215545288302e-09 4.277354710085269e-09
                }
              }
              DEF sr8 HingeJoint {
                jointParameters HingeJointParameters {
                  position 6.550687030701307e-06
                  axis 0 0.707107 0.707107
                  anchor -0.02 -0.03535 0.03535
                }
                endPoint Solid {
                  translation -0.02 -0.03535 0.03535
                  rotation 0 0.7071067811865476 0.7071067811865476 6.550683336067331e-06
                  children [
                    DEF r8 Pose {
                      rotation -1 0 0 0.76
                      children [
                        USE SMALL_WHEEL_SHAPE
                      ]
                    }
                  ]
                  name "sr8"
                  boundingObject USE r8
                  physics Physics {
                    density -1
                    mass 0.1
                  }
                  linearVelocity -5.502804726072489e-08 -1.0429995454305664e-07 -1.2208878138102893e-08
                  angularVelocity 1.110598127739232e-06 -4.234214810330929e-09 4.27735396848549e-09
                }
              }
              DEF WHEEL_TRANS Pose {
                translation -0.02 0 0
                rotation 0 -1 0 1.5708
                children [
                  DEF WHEEL_SHAPE Shape {
                    appearance PBRAppearance {
                      baseColor 0.678431 0.847059 0.901961
                      roughness 1
                      metalness 0
                    }
                    geometry Cylinder {
                      height 0.02
                      radius 0.05
                      subdivision 20
                    }
                  }
                ]
              }
            ]
            boundingObject Pose {
              translation -0.02 0 0
              rotation 0 -1 0 1.5708
              children [
                DEF wheel1 Shape {
                  appearance PBRAppearance {
                    baseColor 0.8 0.8 0.8
                    transparency 0.12999999523162842
                    roughness 1
                    metalness 0
                    emissiveColor 0 1 0
                  }
                  geometry Cylinder {
                    height 0.02
                    radius 0.05
                  }
                }
              ]
            }
            physics Physics {
            }
            linearVelocity -7.160575375737102e-08 -6.506841718563842e-08 2.7046274595789585e-08
            angularVelocity 1.1105959760054314e-06 2.3001545877542487e-07 2.385158020849039e-07
          }
        }
      ]
      name "wheel 1"
      boundingObject DEF DUMMY Sphere {
        radius 0.01
      }
      physics Physics {
      }
    }
    DEF SOLID2 Solid {
      rotation 0 0 1 2.09
      children [
        DEF WHEEL2 HingeJoint {
          jointParameters HingeJointParameters {
            position 1.225219628148875e-07
            axis -1 0 0
            anchor -0.1 0 0
          }
          device [
            RotationalMotor {
              name "wheel2"
            }
          ]
          endPoint Solid {
            translation -0.1 0 0
            rotation -1 0 0 0.0024059325220088528
            children [
              DEF sr1 HingeJoint {
                jointParameters HingeJointParameters {
                  position -2.5563407056949927e-05
                  axis 0 1 0
                  anchor -0.02 0 0.05
                }
                endPoint Solid {
                  translation -0.02 0 0.05
                  rotation 0 -1 0 2.5563409992493185e-05
                  children [
                    USE r1
                  ]
                  name "sr1"
                  boundingObject USE r1
                  physics Physics {
                    density -1
                    mass 0.1
                  }
                  linearVelocity -8.529351719929845e-08 -4.326319299418011e-08 -2.605527392573372e-11
                  angularVelocity 4.3410101876257803e-07 -7.607301183723768e-07 2.385063412390877e-07
                }
              }
              DEF sr2 HingeJoint {
                jointParameters HingeJointParameters {
                  position 1.777194881740425e-05
                  axis 0 -0.707107 0.707107
                  anchor -0.02 0.03535 0.03535
                }
                endPoint Solid {
                  translation -0.02 0.03535 0.03535
                  rotation 0 -0.7071067811865476 0.7071067811865476 1.777195721625451e-05
                  children [
                    USE r2
                  ]
                  name "sr2"
                  boundingObject USE r2
                  physics Physics {
                    density -1
                    mass 0.1
                  }
                  linearVelocity -6.991119042094178e-08 -4.4176477210448374e-08 -3.094775023633878e-08
                  angularVelocity 3.2945468082396995e-07 -8.205395992347533e-07 1.1713300487750584e-07
                }
              }
              DEF sr3 HingeJoint {
                jointParameters HingeJointParameters {
                  position -8.799983452810142e-07
                  axis 0 1 0
                  anchor -0.02 0 -0.05
                }
                endPoint Solid {
                  translation -0.02 0 -0.05
                  rotation 0 -0.9999999999999999 0 8.800520336767149e-07
                  children [
                    USE r3
                  ]
                  name "sr3"
                  boundingObject USE r3
                  physics Physics {
                    density -1
                    mass 0.1
                  }
                  linearVelocity -9.76926315346188e-09 -7.080969029296271e-11 1.8024298671819555e-10
                  angularVelocity 1.857820271205797e-08 -9.98194985101258e-07 2.3730588873892164e-07
                }
              }
              DEF sr4 HingeJoint {
                jointParameters HingeJointParameters {
                  position 1.7771948937958264e-05
                  axis 0 -0.707107 0.707107
                  anchor -0.02 -0.03535 -0.03535
                }
                endPoint Solid {
                  translation -0.02 -0.03535 -0.03535
                  rotation 0 -0.7071067811865475 0.7071067811865475 1.777195721625451e-05
                  children [
                    USE r4
                  ]
                  name "sr4"
                  boundingObject USE r4
                  physics Physics {
                    density -1
                    mass 0.1
                  }
                  linearVelocity -2.4667192844242265e-08 1.1192722279724085e-09 3.1105964683999396e-08
                  angularVelocity 3.2945482306946115e-07 -8.205395123482805e-07 1.1713317737594541e-07
                }
              }
              DEF sr5 HingeJoint {
                jointParameters HingeJointParameters {
                  position -6.417301586824828e-08
                  axis 0 0 1
                  anchor -0.02 0.05 0
                }
                endPoint Solid {
                  translation -0.02 0.05 0
                  rotation 0 0 -1 6.664001874625056e-08
                  children [
                    USE r5
                  ]
                  name "sr5"
                  boundingObject USE r5
                  physics Physics {
                    density -1
                    mass 0.1
                  }
                  linearVelocity -4.128203540070228e-08 -3.182778119647727e-08 -4.3700960718505825e-08
                  angularVelocity 4.3482711307894256e-07 -7.603221773231321e-07 2.302727589731462e-11
                }
              }
              DEF sr6 HingeJoint {
                jointParameters HingeJointParameters {
                  position -6.417302422789817e-08
                  axis 0 0 1
                  anchor -0.02 -0.05 0
                }
                endPoint Solid {
                  translation -0.02 -0.05 0
                  rotation 0 0 -1 6.664001874625056e-08
                  children [
                    USE r6
                  ]
                  name "sr6"
                  boundingObject USE r6
                  physics Physics {
                    density -1
                    mass 0.1
                  }
                  linearVelocity -5.329634797335329e-08 -1.1229424251698656e-08 4.385917460548932e-08
                  angularVelocity 4.3482711721513065e-07 -7.603221741297112e-07 2.3010008323054566e-11
                }
              }
              DEF sr7 HingeJoint {
                jointParameters HingeJointParameters {
                  position -1.8197720214070252e-05
                  axis 0 0.707107 0.707107
                  anchor -0.02 0.03535 -0.03535
                }
                endPoint Solid {
                  translation -0.02 0.03535 -0.03535
                  rotation 0 -0.7071067811865476 -0.7071067811865476 1.8197728533733993e-05
                  children [
                    USE r7
                  ]
                  name "sr7"
                  boundingObject USE r7
                  physics Physics {
                    density -1
                    mass 0.1
                  }
                  linearVelocity -1.617307391089543e-08 -1.3443766171853995e-08 -3.0799051461473115e-08
                  angularVelocity 5.375513437333362e-07 -7.016112383997613e-07 1.201855189740183e-07
                }
              }
              DEF sr8 HingeJoint {
                jointParameters HingeJointParameters {
                  position -1.819772205080742e-05
                  axis 0 0.707107 0.707107
                  anchor -0.02 -0.03535 0.03535
                }
                endPoint Solid {
                  translation -0.02 -0.03535 0.03535
                  rotation 0 -0.7071067811865475 -0.7071067811865475 1.8197728533733993e-05
                  children [
                    USE r8
                  ]
                  name "sr8"
                  boundingObject USE r8
                  physics Physics {
                    density -1
                    mass 0.1
                  }
                  linearVelocity -7.84053094901446e-08 -2.9613439146524596e-08 3.09572652318916e-08
                  angularVelocity 5.375535667754826e-07 -7.016099624486396e-07 1.201829641147072e-07
                }
              }
              USE WHEEL_TRANS
            ]
            boundingObject Pose {
              translation -0.02 0 0
              rotation 0 -1 0 1.5708
              children [
                DEF wheel1 Shape {
                  appearance PBRAppearance {
                    baseColor 0.8 0.8 0.8
                    transparency 0.12999999523162842
                    roughness 1
                    metalness 0
                    emissiveColor 0 1 0
                  }
                  geometry Cylinder {
                    height 0.02
                    radius 0.05
                  }
                }
              ]
            }
            physics Physics {
            }
            linearVelocity -4.7302938385427794e-08 -2.153661164189616e-08 7.90602537664322e-11
            angularVelocity 4.343267548258173e-07 -7.606011346070436e-07 2.3850696992738064e-07
          }
        }
      ]
      name "wheel 2"
      boundingObject USE DUMMY
      physics Physics {
      }
    }
    DEF SOLID3 Solid {
      rotation 0 0 1 4.18
      children [
        DEF WHEEL3 HingeJoint {
          jointParameters HingeJointParameters {
            position -1.2441679770578496e-07
            axis -1 0 0
            anchor -0.1 0 0
          }
          device [
            RotationalMotor {
              name "wheel3"
            }
          ]
          endPoint Solid {
            translation -0.1 0 0
            rotation -1 0 0 0.003909315583145444
            children [
              DEF sr1 HingeJoint {
                jointParameters HingeJointParameters {
                  position 1.5770951793699228e-05
                  axis 0 1 0
                  anchor -0.02 0 0.05
                }
                endPoint Solid {
                  translation -0.02 0 0.05
                  rotation 0 0.9999999999999999 0 1.5770948611889293e-05
                  children [
                    USE r1
                  ]
                  name "sr1"
                  boundingObject USE r1
                  physics Physics {
                    density -1
                    mass 0.1
                  }
                  linearVelocity -1.4500573231696013e-07 2.1255152478174732e-08 -2.673956173119101e-08
                  angularVelocity -6.328347314427086e-07 -1.0760050888824512e-06 2.3762668696782587e-07
                }
              }
              DEF sr2 HingeJoint {
                jointParameters HingeJointParameters {
                  position -1.0950188443013804e-05
                  axis 0 -0.707107 0.707107
                  anchor -0.02 0.03535 0.03535
                }
                endPoint Solid {
                  translation -0.02 0.03535 0.03535
                  rotation 0 0.7071067811865475 -0.7071067811865475 1.0950194116775991e-05
                  children [
                    USE r2
                  ]
                  name "sr2"
                  boundingObject USE r2
                  physics Physics {
                    density -1
                    mass 0.1
                  }
                  linearVelocity -1.2656151793974747e-07 1.6205398089603916e-08 1.730585509702969e-08
                  angularVelocity -6.308680998257413e-07 -1.0771679976762426e-06 3.1669047384965644e-09
                }
              }
              DEF sr3 HingeJoint {
                jointParameters HingeJointParameters {
                  position -1.1667135151327557e-06
                  axis 0 1 0
                  anchor -0.02 0 -0.05
                }
                endPoint Solid {
                  translation -0.02 0 -0.05
                  rotation 0 -1 0 1.1668665379555326e-06
                  children [
                    USE r3
                  ]
                  name "sr3"
                  boundingObject USE r3
                  physics Physics {
                    density -1
                    mass 0.1
                  }
                  linearVelocity -5.0126644157309644e-08 -6.146042661815095e-08 -2.6689948490921175e-08
                  angularVelocity 6.121434349352424e-06 -5.055137114044645e-06 2.0708734201514538e-07
                }
              }
              DEF sr4 HingeJoint {
                jointParameters HingeJointParameters {
                  position -1.095018941299486e-05
                  axis 0 -0.707107 0.707107
                  anchor -0.02 -0.03535 -0.03535
                }
                endPoint Solid {
                  translation -0.02 -0.03535 -0.03535
                  rotation 0 0.7071067811865476 -0.7071067811865476 1.0950194116775991e-05
                  children [
                    USE r4
                  ]
                  name "sr4"
                  boundingObject USE r4
                  physics Physics {
                    density -1
                    mass 0.1
                  }
                  linearVelocity -6.765811055156973e-08 -5.6961572776496914e-08 -7.126998893226148e-08
                  angularVelocity -6.308669416968894e-07 -1.0771686764672076e-06 3.165548160546097e-09
                }
              }
              DEF sr5 HingeJoint {
                jointParameters HingeJointParameters {
                  position 5.89869488513807e-08
                  axis 0 0 1
                  anchor -0.02 0.05 0
                }
                endPoint Solid {
                  translation -0.02 0.05 0
                  rotation 0 0 0.9999999999999999 5.960464477539063e-08
                  children [
                    USE r5
                  ]
                  name "sr5"
                  boundingObject USE r5
                  physics Physics {
                    density -1
                    mass 0.1
                  }
                  linearVelocity -9.087118580838195e-08 -1.0266652004256688e-08 3.54174662492315e-08
                  angularVelocity -8.328778073588597e-07 -9.58157924457795e-07 9.190690322564822e-10
                }
              }
              DEF sr6 HingeJoint {
                jointParameters HingeJointParameters {
                  position 5.898696394950521e-08
                  axis 0 0 1
                  anchor -0.02 -0.05 0
                }
                endPoint Solid {
                  translation -0.02 -0.05 0
                  rotation 0 0 1 5.960464477539063e-08
                  children [
                    USE r6
                  ]
                  name "sr6"
                  boundingObject USE r6
                  physics Physics {
                    density -1
                    mass 0.1
                  }
                  linearVelocity -1.0334844310996437e-07 -3.0489522705846746e-08 -8.938160075124021e-08
                  angularVelocity -8.32877801951785e-07 -9.581579223506107e-07 9.190993638769553e-10
                }
              }
              DEF sr7 HingeJoint {
                jointParameters HingeJointParameters {
                  position 1.1240463821031733e-05
                  axis 0 0.707107 0.707107
                  anchor -0.02 0.03535 -0.03535
                }
                endPoint Solid {
                  translation -0.02 0.03535 -0.03535
                  rotation 0 0.7071067811865475 0.7071067811865475 1.124045466583865e-05
                  children [
                    USE r7
                  ]
                  name "sr7"
                  boundingObject USE r7
                  physics Physics {
                    density -1
                    mass 0.1
                  }
                  linearVelocity -5.883668975612733e-08 -4.266400323036043e-08 1.6962952190829597e-08
                  angularVelocity -8.339686047687343e-07 -9.575109874289115e-07 2.3635074575308765e-07
                }
              }
              DEF sr8 HingeJoint {
                jointParameters HingeJointParameters {
                  position 1.1240463946544505e-05
                  axis 0 0.707107 0.707107
                  anchor -0.02 -0.03535 0.03535
                }
                endPoint Solid {
                  translation -0.02 -0.03535 0.03535
                  rotation 0 0.7071067811865476 0.7071067811865476 1.124045466583865e-05
                  children [
                    USE r8
                  ]
                  name "sr8"
                  boundingObject USE r8
                  physics Physics {
                    density -1
                    mass 0.1
                  }
                  linearVelocity -1.3538293898291742e-07 1.9078284617761158e-09 -7.092708560862126e-08
                  angularVelocity -8.339684462803081e-07 -9.575110747675155e-07 2.3635091443164032e-07
                }
              }
              USE WHEEL_TRANS
            ]
            boundingObject Pose {
              translation -0.02 0 0
              rotation 0 -1 0 1.5708
              children [
                DEF wheel1 Shape {
                  appearance PBRAppearance {
                    baseColor 0.8 0.8 0.8
                    transparency 0.12999999523162842
                    roughness 1
                    metalness 0
                    emissiveColor 0 1 0
                  }
                  geometry Cylinder {
                    height 0.02
                    radius 0.05
                  }
                }
              ]
            }
            physics Physics {
            }
            linearVelocity -9.713512599425324e-08 -2.0385791408490252e-08 -2.6989516581812128e-08
            angularVelocity -8.320797057825178e-07 -9.586237791002576e-07 2.385260917204522e-07
          }
        }
      ]
      name "wheel 3"
      boundingObject USE DUMMY
      physics Physics {
      }
    }
    DEF BODY_TRANS Pose {
      translation 0 0 0.03
      children [
        Shape {
          appearance PBRAppearance {
            baseColor 0.564706 0.933333 0.564706
            roughness 1
            metalness 0
          }
          geometry Cylinder {
            height 0.15
            radius 0.1
            subdivision 18
          }
        }
      ]
    }
  ]
  boundingObject USE BODY_TRANS
  physics Physics {
  }
  controller "keyboard_kinematics"
  linearVelocity -6.491965176605451e-08 -3.159532599779204e-08 4.5023721387680346e-11
  angularVelocity -1.3182338046672252e-07 2.3002881833063301e-07 2.3853753639222387e-07
}
